Workbook

Sheet 说明与调参指南
A1: 《捡漏》数值框架 v1.0
A2: 浅黄底色的列都是公式，改上游参数会自动重算。改完请先看「概率合计」两处校验是否仍为 100%。
A3: 工作表 | B3: 作用 | C3: 调参提示
A4: 稀有度定义 | B4: 五档稀有度的材料回收价、图鉴点、街头平均单件价 | C4: 全局基准，改动会同时影响盲盒与区域两张表，建议最后再调。
A5: 盲盒配置 | B5: 五种盲盒的售价、概率与保底计数，自动算货币EV、返还率、图鉴点期望 | C5: 「材料返还率」目标 55%–65%。高于 70% 玩家就不需要肝了；低于 50% 会觉得被坑。
A6: 街头垃圾表 | B6: 街头可拾取物品清单（品类 / 稀有度 / 主要区域 / 区域 id / 重量 / 单价 / 格数） | C6: 「区域 id」列是 config/items.json → zones 的映射来源（多区域用英文逗号连接），本表行序与 config/items.json 严格一致；紫金件单价可以给高，但区域出现率必须极低，否则经济瞬间崩。
A7: 区域配置 | B7: 六区域的解锁条件、体力消耗、稀有度概率分布 | C7: 看「每体力收益」列：相邻区域差距控制在 10% 以内，保证老区域不作废。
A8: 载具与升级 | B8: 五级载具的格数与升级成本，算攒钱趟数与回收趟数 | C8: 「攒钱趟数」8–18 趟最舒服。低于 5 趟升级没成就感，高于 25 趟会劝退。
A10: 核心模型 | B10: 单趟收益 = 载具格数 × 该区域平均单件价值
B11: 平均单件价值 = Σ(各稀有度概率 × 该档街头均价) | C11: 所以「区域」决定捡到什么，「载具」决定一趟能带多少。
A13: 品相与结算（对应 config/global.json → sell）
A14: 品相 | B14: 售价系数 | C14: 出现权重
A15: 完好 pristine | B15: 1 | C15: 0.5
A16: 磨损 worn | B16: 0.8 | C16: 0.35
A17: 破损 broken | B17: 0.5 | C17: 0.15
A18: 结算公式 | B18: 实际售价 = 回收单价 × 品相系数 × 区域价格系数（区域价格系数 0.85–1.25，见 config/global.json → sell.zonePriceModifier）。出现权重合计必须 = 100%。
A20: 等级与区域解锁（对应 config/global.json → level）
A21: 经验来源 | B21: 累计出售额 × expPerCurrency（首版 1 元 = 1 经验）
A22: 等级 | B22: 1 | C22: 2 | D22: 3 | E22: 4 | F22: 5 | G22: 6 | H22: 7 | I22: 8 | J22: 9 | K22: 10 | L22: 11 | M22: 12 | N22: 13 | O22: 14 | P22: 15 | Q22: 16 | R22: 17 | S22: 18 | T22: 19 | U22: 20
A23: 累计经验 | B23: 0 | C23: 20 | D23: 50 | E23: 90 | F23: 140 | G23: 200 | H23: 280 | I23: 380 | J23: 500 | K23: 640 | L23: 800 | M23: 1000 | N23: 1250 | O23: 1550 | P23: 1900 | Q23: 2300 | R23: 2800 | S23: 3400 | T23: 4100 | U23: 4900
A24: 区域解锁 | B24: Lv3 商业街区 · Lv6 老旧小区 · Lv10 建设工地 · Lv15 老城区 · Lv20 城郊填埋场
A25: 节奏参照 | B25: Lv3 约 6 趟（手提袋 @街头巷尾 9 元/趟）、Lv6 约 8 趟（小推车 26.6 元/趟），对应策划案「20 分钟内解锁第二区域」。
A27: 背包扩容与假点（对应 config/global.json → grids、config/zones.json → emptyPointRate）
A28: 每次扩容格数 | B28: 2 | C28: 首次扩容 10 元 / +2 格（对齐策划案 05 节节奏表）
A29: 每格成本(元) | B29: 5 | C29: 背包容量 = 载具格数 + 已扩容格数
A30: 假点概率 | B30: 街头巷尾 0.20 / 商业街区 0.18 / 老旧小区 0.16 / 建设工地 0.15 / 老城区 0.14 / 城郊填埋场 0.12 | C30: 假点 = 已空的垃圾点，点击只提示「空空如也」
A32: 保底规则（对应 config/gacha.json → pity 与每款盲盒的 pityCounter）
A33: 目标档 | B33: 紫（pity.targetRarity）——金也视为达标
A34: 计数方式 | B34: 每盒独立计数（scope=per_box），抽到紫以上即清零（resetOnHit=true）
A35: 计数取值 | B35: 废品 150 / 家电 15 / 古董 10 / 记忆 15 / 限定 10 —— 判据是「含保底实测返还率 ≤ 65%」：保底那一次的收入不能超过凑够保底的累计成本，否则玩家只买保底就能刷钱（材料可卖成钱）
A36: 校验方式 | B36: 含保底实测返还率有解析解，由 `npm run check-config` 计算并校验（必须落 55%–65%）；config/gacha.json 的 returnRateWithPity 是该值的派生列
A37: 新手保护 | B37: 每账号首次开箱必出蓝以上，与保底相互独立
A38: 为什么便宜盒保底反而更远 | B38: 紫的材料回收价 120 元 = 废品盲盒售价的 12 倍，保底 10 抽的话「10×10 元成本 vs 120 元收入」结构性亏本；古董/限定盒紫金概率本来就高，10 抽几乎不会触发，所以取小值即可。
A40: 体力与恢复（对应 config/global.json → player）
A41: 初始 / 上限 | B41: 60 / 60
A42: 恢复速率 | B42: 0.5 点/分钟（30 点/小时）
A43: 满仓时长 | B43: 2 小时 = 上限 ÷ 速率。必须落在 90–240 分钟：低于 90 体力形同取消，高于 240 一天玩不到 3 次（原 0.125 点/分钟 = 8 小时，已按此判据调高）
A44: 离线封顶 | B44: 8 小时（offlineStaminaCapHours），必须 ≥ 满仓时长，否则玩家回来还没回满；上限 60 / 速率 0.5 时该封顶不会生效，仅作防御
A45: 单次会话用量 | B45: 一次会话 3–6 趟 ≈ 30–60 体力 ≈ 一个满仓，所以「满仓时长」就是两次会话之间的节奏
A46: 广告恢复 | B46: 30 点 / 次、每天 3 次（= 1 小时自然恢复量）
...

Sheet 稀有度定义
A1: 稀有度 | B1: 名称 | C1: 材料回收价(元/件) | D1: 图鉴点(点) | E1: 街头平均单件价(元) | G1: 说明
A2: 白 | B2: 普通 | C2: 1 | D2: 1 | E2: 0.05 | G2: 「材料回收价」= 盲盒开出后可直接卖成钱的单价（返还率的分子）
A3: 绿 | B3: 优良 | C3: 4 | D3: 6 | E3: 1 | G3: 「图鉴点」= 藏品不可出售，只贡献图鉴进度，是长线目标
A4: 蓝 | B4: 稀有 | C4: 18 | D4: 30 | E4: 15 | G4: 「街头平均单件价」= 街头拾取到的该档物品平均值，用于区域收益估算
A5: 紫 | B5: 史诗 | C5: 120 | D5: 150 | E5: 150
A6: 金 | B6: 传说 | C6: 600 | D6: 800 | E6: 700

Sheet 盲盒配置
A1: 盲盒名称 | B1: 售价(元) | C1: 白 | D1: 绿 | E1: 蓝 | F1: 紫 | G1: 金 | H1: 概率合计(校验) | I1: 货币EV(元) | J1: 材料返还率 | K1: 图鉴点期望(点) | L1: 定位 | M1: 保底计数（未出紫）
A2: 废品盲盒 | B2: 10 | C2: 0.65 | D2: 0.26 | E2: 0.07 | F2: 0.018 | G2: 0.002 | H2: =SUM(C2:G2) -> 1 | I2: =C2*稀有度定义!$C$2+D2*稀有度定义!$C$3+E2*稀有度定义!$C$4+F2*稀有度定义!$C$5+G2*稀有度定义!$C$6 -> 6.31 | J2: =I2/B2 -> 0.631 | K2: =C2*稀有度定义!$D$2+D2*稀有度定义!$D$3+E2*稀有度定义!$D$4+F2*稀有度定义!$D$5+G2*稀有度定义!$D$6 -> 8.61 | L2: 新手入门，随便赌 | M2: 150
A3: 家电盲盒 | B3: 60 | C3: 0.2 | D3: 0.27 | E3: 0.38 | F3: 0.13 | G3: 0.02 | H3: =SUM(C3:G3) -> 1 | I3: =C3*稀有度定义!$C$2+D3*稀有度定义!$C$3+E3*稀有度定义!$C$4+F3*稀有度定义!$C$5+G3*稀有度定义!$C$6 -> 35.72 | J3: =I3/B3 -> 0.59533333 | K3: =C3*稀有度定义!$D$2+D3*稀有度定义!$D$3+E3*稀有度定义!$D$4+F3*稀有度定义!$D$5+G3*稀有度定义!$D$6 -> 48.72 | L3: 主力款，出货体感最好 | M3: 15
A4: 古董盲盒 | B4: 200 | C4: 0.04 | D4: 0.12 | E4: 0.3 | F4: 0.42 | G4: 0.12 | H4: =SUM(C4:G4) -> 1 | I4: =C4*稀有度定义!$C$2+D4*稀有度定义!$C$3+E4*稀有度定义!$C$4+F4*稀有度定义!$C$5+G4*稀有度定义!$C$6 -> 128.32 | J4: =I4/B4 -> 0.6416 | K4: =C4*稀有度定义!$D$2+D4*稀有度定义!$D$3+E4*稀有度定义!$D$4+F4*稀有度定义!$D$5+G4*稀有度定义!$D$6 -> 168.76 | L4: 高价值款，追紫金 | M4: 10
A5: 记忆盲盒 | B5: 80 | C5: 0.2 | D5: 0.3 | E5: 0.3 | F5: 0.16 | G5: 0.04 | H5: =SUM(C5:G5) -> 1 | I5: =C5*稀有度定义!$C$2+D5*稀有度定义!$C$3+E5*稀有度定义!$C$4+F5*稀有度定义!$C$5+G5*稀有度定义!$C$6 -> 50 | J5: =I5/B5 -> 0.625 | K5: =C5*稀有度定义!$D$2+D5*稀有度定义!$D$3+E5*稀有度定义!$D$4+F5*稀有度定义!$D$5+G5*稀有度定义!$D$6 -> 67 | L5: 剧情专属，货币回报低 | M5: 15
A6: 限定盲盒 | B6: 300 | C6: 0.02 | D6: 0.08 | E6: 0.25 | F6: 0.45 | G6: 0.2 | H6: =SUM(C6:G6) -> 1 | I6: =C6*稀有度定义!$C$2+D6*稀有度定义!$C$3+E6*稀有度定义!$C$4+F6*稀有度定义!$C$5+G6*稀有度定义!$C$6 -> 178.84 | J6: =I6/B6 -> 0.59613333 | K6: =C6*稀有度定义!$D$2+D6*稀有度定义!$D$3+E6*稀有度定义!$D$4+F6*稀有度定义!$D$5+G6*稀有度定义!$D$6 -> 235.5 | L6: 活动限定，含绝版外观 | M6: 10
A8: 校验与调参
A9: ①「概率合计」必须 = 100%，否则概率配置有误。
A10: ②「材料返还率」目标 55%–65%：差额由「图鉴点期望 + 保底 + 新手保护」在体感上补足。
A11: ③ 货币EV = Σ(各档概率 × 材料回收价)，已按售价折算返还率；改「稀有度定义」会自动联动。
A12: ④ 新手保护：玩家首次开箱必出蓝以上，不受本表概率约束（单独逻辑）。

Sheet 街头垃圾表
A1: 品类 | B1: 稀有度 | C1: 主要区域 | D1: 重量(kg/件) | E1: 回收单价(元/件) | F1: 占用格数 | G1: 备注 | H1: 区域 id（供 config 映射）
A2: 塑料瓶 | B2: 白 | C2: 全区 | D2: 0.03 | E2: 0.05 | F2: 1 | G2: 最基础，量大 | H2: all
A3: 易拉罐 | B3: 白 | C3: 全区 | D3: 0.02 | E3: 0.08 | F3: 1 | G3: 老王日常任务指定物 | H3: all
A4: 传单纸 | B4: 白 | C4: 商业街区 | D4: 0.01 | E4: 0.02 | F4: 1 | G4: 几乎不值钱，占格子 | H4: shopping_street
A5: 废纸箱 | B5: 绿 | C5: 商业街区 | D5: 0.5 | E5: 0.6 | F5: 1 | G5: 量大，需拆解 | H5: shopping_street
A6: 玻璃瓶 | B6: 绿 | C6: 老旧小区 | D6: 0.4 | E6: 0.5 | F6: 1 | G6: 易碎，掉落率受手套影响 | H6: old_apartment
A7: 旧衣服 | B7: 绿 | C7: 老旧小区 | D7: 0.6 | E7: 1.2 | F7: 1 | G7: 轻，性价比不错 | H7: old_apartment
A8: 废旧轮胎 | B8: 绿 | C8: 建设工地 | D8: 6 | E8: 4 | F8: 2 | G8: 极重，占 2 格 | H8: construction_site
A9: 藤编旧筐 | B9: 绿 | C9: 街头巷尾、老城区、城郊填埋场 | D9: 0.6 | E9: 1 | F9: 1 | G9: 补齐街头巷尾/老城区/填埋场的绿档空缺 | H9: street_alley,old_town,landfill
A10: 破铜线 | B10: 蓝 | C10: 建设工地 | D10: 0.2 | E10: 6 | F10: 1 | G10: 工地特产，轻且值钱 | H10: construction_site
A11: 旧手机 | B11: 蓝 | C11: 老旧小区 | D11: 0.18 | E11: 15 | F11: 1 | G11: 小区特产 | H11: old_apartment
A12: 旧家电 | B12: 蓝 | C12: 老旧小区 | D12: 3.5 | E12: 25 | F12: 3 | G12: 占 3 格，需三轮车 | H12: old_apartment
A13: 旧收音机 | B13: 蓝 | C13: 街头巷尾、商业街区、老城区、城郊填埋场 | D13: 0.35 | E13: 15 | F13: 1 | G13: 补齐四处区域的蓝档空缺（老旧小区已有蓝档） | H13: street_alley,shopping_street,old_town,landfill
... A22: 老怀表 | B22: 金 | C22: 建设工地、城郊填埋场 | D22: 0.1 | E22: 700 | F22: 1 | G22: 补齐建设工地/填埋场的金档空缺 | H22: construction_site,landfill

Sheet 区域配置
A1: 区域 | B1: 解锁等级 | C1: 单趟体力 | D1: 平均单件价值(元/件) | E1: 白 | F1: 绿 | G1: 蓝 | H1: 紫 | I1: 金 | J1: 概率合计(校验) | K1: 每体力收益(元/体力,@12格) | L1: 垃圾特征 | M1: 假点概率
A2: 街头巷尾 | B2: 1 | C2: 10 | D2: =E2*稀有度定义!$E$2+F2*稀有度定义!$E$3+G2*稀有度定义!$E$4+H2*稀有度定义!$E$5+I2*稀有度定义!$E$6 -> 1.5 | E2: 0.62 | F2: 0.34092857 | G2: 0.035871429 | H2: 0.003 | I2: 0.0002 | J2: =SUM(E2:I2) -> 1 | K2: =D2*12/C2 -> 1.8 | M2: 0.2
A3: 商业街区 | B3: 3 | C3: 14 | D3: =E3*稀有度定义!$E$2+F3*稀有度定义!$E$3+G3*稀有度定义!$E$4+H3*稀有度定义!$E$5+I3*稀有度定义!$E$6 -> 2.2166667 | E3: 0.56 | F3: 0.38288095 | G3: 0.051719048 | H3: 0.005 | I3: 0.0004 | J3: =SUM(E3:I3) -> 1 | K3: =D3*12/C3 -> 1.9 | M3: 0.18
A4: 老旧小区 | B4: 6 | C4: 18 | D4: =E4*稀有度定义!$E$2+F4*稀有度定义!$E$3+G4*稀有度定义!$E$4+H4*稀有度定义!$E$5+I4*稀有度定义!$E$6 -> 3 | E4: 0.5 | F4: 0.42971429 | G4: 0.061685714 | H4: 0.008 | I4: 0.0006 | J4: =SUM(E4:I4) -> 1 | K4: =D4*12/C4 -> 2 | M4: 0.16
A5: 建设工地 | B5: 10 | C5: 24 | D5: =E5*稀有度定义!$E$2+F5*稀有度定义!$E$3+G5*稀有度定义!$E$4+H5*稀有度定义!$E$5+I5*稀有度定义!$E$6 -> 4.24 | E5: 0.44 | F5: 0.46335714 | G5: 0.083642857 | H5: 0.012 | I5: 0.001 | J5: =SUM(E5:I5) -> 1 | K5: =D5*12/C5 -> 2.12 | M5: 0.15
A6: 老城区 | B6: 15 | C6: 30 | D6: =E6*稀有度定义!$E$2+F6*稀有度定义!$E$3+G6*稀有度定义!$E$4+H6*稀有度定义!$E$5+I6*稀有度定义!$E$6 -> 5.6 | E6: 0.39 | F6: 0.50192857 | G6: 0.088571429 | H6: 0.018 | I6: 0.0015 | J6: =SUM(E6:I6) -> 1 | K6: =D6*12/C6 -> 2.24 | M6: 0.14
A7: 城郊填埋场 | B7: 20 | C7: 40 | D7: =E7*稀有度定义!$E$2+F7*稀有度定义!$E$3+G7*稀有度定义!$E$4+H7*稀有度定义!$E$5+I7*稀有度定义!$E$6 -> 7.8333333 | E7: 0.34 | F7: 0.4877619 | G7: 0.1452381 | H7: 0.025 | I7: 0.002 | J7: =SUM(E7:I7) -> 1 | K7: =D7*12/C7 -> 2.35 | M7: 0.12
A9: 调参提示：相邻两区域的「每体力收益」差距建议 ≤ 10%，否则新区域一开旧区域就作废（本表已按 +5.6%/档 生成）。
A10: 模型说明：区域决定「捡到什么」（稀有度分布 → 平均单件价值），载具格数决定「一趟能带多少」，两者相乘才是单趟收益。

Sheet 载具与升级
A1: 升级 | B1: 升级前格数 | C1: 升级后格数 | D1: 升级成本(元) | E1: 升级前常驻区域 | F1: 升级后常驻区域 | G1: 升级前单趟收益(元) | H1: 升级后单趟收益(元) | I1: 攒钱趟数(趟) | J1: 回收趟数(趟) | K1: 体验提示
A2: 手提袋 → 小推车 | B2: 6 | C2: 12 | D2: 80 | E2: 街头巷尾 | F2: 商业街区 | G2: =B2*VLOOKUP(E2,区域配置!$A$2:$D$7,4,FALSE) -> 9 | H2: =C2*VLOOKUP(F2,区域配置!$A$2:$D$7,4,FALSE) -> 26.6 | I2: =D2/G2 -> 8.8888889 | J2: =D2/H2 -> 3.0075188 | K2: 首次升级必须 20 分钟内可达成，这是新手留存的关键一跳。
A3: 小推车 → 三轮车 | B3: 12 | C3: 24 | D3: 350 | E3: 商业街区 | F3: 建设工地 | G3: =B3*VLOOKUP(E3,区域配置!$A$2:$D$7,4,FALSE) -> 26.6 | H3: =C3*VLOOKUP(F3,区域配置!$A$2:$D$7,4,FALSE) -> 101.76 | I3: =D3/G3 -> 13.157895 | J3: =D3/H3 -> 3.4394654 | K3: 中期主力升级，应伴随「旧家电终于装得下」的爽点。
A4: 三轮车 → 电瓶车 | B4: 24 | C4: 40 | D4: 1200 | E4: 建设工地 | F4: 老城区 | G4: =B4*VLOOKUP(E4,区域配置!$A$2:$D$7,4,FALSE) -> 101.76 | H4: =C4*VLOOKUP(F4,区域配置!$A$2:$D$7,4,FALSE) -> 224 | I4: =D4/G4 -> 11.792453 | J4: =D4/H4 -> 5.3571429 | K4: 玩家已进入每日上线节奏，可配合广告加速。
A5: 电瓶车 → 小货车 | B5: 40 | C5: 70 | D5: 4000 | E5: 老城区 | F5: 城郊填埋场 | G5: =B5*VLOOKUP(E5,区域配置!$A$2:$D$7,4,FALSE) -> 224 | H5: =C5*VLOOKUP(F5,区域配置!$A$2:$D$7,4,FALSE) -> 548.33333 | I5: =D5/G5 -> 17.857143 | J5: =D5/H5 -> 7.2948328 | K5: 长线目标，应显示「还差多少趟」的进度条。
A7: 调参提示：「攒钱趟数」= 升级成本 ÷ 升级前单趟收益，控制在 8–18 趟。低于 5 趟升级没成就感，高于 25 趟会劝退。
A8: 「回收趟数」= 升级成本 ÷ 升级后单趟收益，反映升级本身的性价比，控制在 3–8 趟。
